Workbook

Sheet Tablero Compra
J2: Aceitera de Soja | O2: Desarrollado por Simpleza S.A.
J3: Tablero de Sensibilidad del Negocio.
B7: Condiciones Venta
K8: Margen de Ventas | N8: =Molienda!O46 -> 11.676746 | P8: =Molienda!P46 -> 91.078616
C9: Precio de Venta Aceite de Soja | E9: =Molienda!E10 -> 620 | F9: u$s/Tn | G9: =Molienda!G10 -> 4836 | H9: $/Tn
C11: Precio de Venta Expeller de Soja 6%MG | E11: =Molienda!E12 -> 334 | F11: u$s/Tn | G11: =Molienda!G12 -> 2605.2 | H11: $/Tn
F12: 713
C14: Flete Venta Aceite | E14: =Molienda!E26 -> 0 | G14: =Molienda!G26 -> 0 | H14: Costo P.G. | K14: Precio Indiferencia Poroto de Soja | N14: =Molienda!O43 -> 314.67675 | P14: =Molienda!P43 -> 2454.4786
C15: Flete Venta Expeller | E15: =Molienda!E27 -> 0 | F15: 0 | G15: =Molienda!G27 -> 0 | H15: Costo P.G.
B18: Condiciones Compra
C20: Precio de Compra Soja (A retirar Campo) | E20: =Molienda!E17 -> 303 | F20: u$s/Tn | G20: =Molienda!G17 -> 2363.4 | H20: $/Tn | K20: Precio Equivalente Puerto Rosario | N20: =Molienda!E49 -> 327.14103 | P20: =Molienda!F49 -> 2551.7
C23: Flete Campo a Planta Km | E23: =Molienda!E29 -> 0 | G23: =Molienda!G29 -> 0 | H23: Costo P.G.
C24: Flete Campo a Puerto Km | E24: =Molienda!E30 -> 445 | F24: 360 | G24: =Molienda!G30 -> 188.3 | H24: Calculo Eq.

Sheet Molienda
I3: Aceitera de Soja | P3: Desarrollado por Simpleza S.A.
I4: Tablero de Sensibilidad del Negocio.
B8: Variables relevantes
Q9: Insumos y Productos del Proceso
C10: Precio de Venta Aceite de Soja | E10: 620 | F10: u$s/Tn | G10: =E10*$E$20 -> 4836 | H10: $/Tn | J10: Proporción Aceite | L10: =M10/1000 -> 0.14 | M10: 140
C12: Precio de Venta Expellet de Soja 6%MG | E12: 334 | F12: u$s/Tn | G12: =E12*$E$20 -> 2605.2 | H12: $/Tn | J12: Proporción Harina de Soja | L12: =1-L10 -> 0.86
T13: =CONCATENATE(W13," ",ROUND(X13,0),"Tn") -> Poroto Soja 650Tn | W13: Poroto Soja | X13: =L20 -> 650
C14: Precio de Venta Harina de Soja | E14: 334 | F14: u$s/Tn | G14: =E14*$E$20 -> 2605.2 | H14: $/Tn | T14: =CONCATENATE(W14," ",ROUND(X14,0),"Tn") -> Mermas 25Tn | W14: Mermas | X14: =X13*E37 -> 25.418994
J15: Pellet de Soja 6% MG | L15: =M15/1000 -> 1 | M15: 1000 | T15: =CONCATENATE(W15," ",ROUND(X15,0),"Tn") -> Aceite 87Tn | W15: Aceite | X15: =(X13-X14)*L10 -> 87.441341
T16: =CONCATENATE(W16," ",ROUND(X16,0),"Tn") -> Harina 537Tn | W16: Harina | X16: =(X13-X14)*L12 -> 537.13966
C17: Precio de Compra Soja (A retirar Campo) | E17: 303 | F17: u$s/Tn | G17: =E17*$E$20 -> 2363.4 | H17: $/Tn | J17: Harina de Soja | L17: =1-L15 -> 0 | T17: =CONCATENATE(W17," ",ROUND(X17,0),"Tn") -> Pellet 6% 537Tn | W17: Pellet 6% | X17: =X16*L15 -> 537.13966
T18: =CONCATENATE(W18," ",ROUND(X18,0),"Tn") -> Harina 0Tn | W18: Harina | X18: =X16*L17 -> 0
C20: Tipo de Cambio | E20: 7.8 | F20: $/U$S | G20: 628 | J20: Molineda Poroto de Soja | L20: 650 | M20: Tn/mes
C24: Costo de Secada 14 a 10.5ᴼ | E24: =G24/E20 -> 1.6666667 | F24: u$s/Tn | G24: 13 | H24: $/Tn | J24: Molienda 23 a 18 hs | L24: =L20*N24/100 -> 650 | M24: Tn/mes | N24: 100
J25: Molienda 18 a 23 hs | L25: =L20-L24 -> 0
C26: Flete Venta Aceite | E26: 0 | G26: =SUMPRODUCT((E26='Flete y Mermas'!A2:A1001)*('Flete y Mermas'!B2:B1001)) -> 0 | J26: Multa (Molienda Hora Pico) | L26: =IF(L25>0,P82*O82,0)/E20 -> 0 | M26: U$S/Mes
C27: Flete Venta Expeler | E27: 0 | F27: 0 | G27: =SUMPRODUCT((E27='Flete y Mermas'!A2:A1001)*('Flete y Mermas'!B2:B1001)) -> 0 | O27: Aceite | P27: =L10*(1-E37) -> 0.13452514
J28: Coberturas MAT | L28: 0 | M28: Tn/mes
C29: Flete Campo a Planta Km | E29: 0 | G29: =SUMPRODUCT((E29='Flete y Mermas'!A2:A1001)*('Flete y Mermas'!B2:B1001)) -> 0
C30: Flete Campo a Puerto Km | E30: 445 | F30: 0 | G30: =SUMPRODUCT((E30='Flete y Mermas'!A2:A1001)*('Flete y Mermas'!B2:B1001)) -> 188.3 | J30: Costo Cobertura U$S/Tn | L30: =M30/10 -> 0 | M30: 0
O31: Pellet | P31: =L12*(1-E37)*L15 -> 0.82636872
C32: Comisiones de Compra Soja | E32: =F32/1000 -> 0 | F32: 0 | O32: Mermas | P32: =E37 -> 0.039106145
C33: Comisiones de Venta Aceite | E33: =F33/1000 -> 0.005 | F33: 5
C34: Comisiones de Venta Pellet | E34: =F34/1000 -> 0.005 | F34: 5
C37: Ineficiencia total Mermas del Proceso | E37: =SUM(K37,K38,P37,P38) -> 0.039106145 | F37: Mermar sobre poroto de soja ingresado | H37: Mermas Humedad 14 a 10,5 | K37: =(14-10.5)/(100-10.5) -> 0.039106145 | L37: 0 | N37: Mermas Acondicionado | P37: =Q37/1000 -> 0 | Q37: 0
H38: Mermas Descascarado | K38: =L38/1000 -> 0 | L38: 0 | N38: Mermas Estruzado | P38: =Q38/1000 -> 0 | Q38: 0
B41: Indicadores del Negocio
C43: Margen de Ventas | E43: =E89/E56 -> 0.032488402 | G43: Precio Indiferencia Aceite | I43: =F60+F76-F58 -> 533.20027 | K43: =I43*$E$20 -> 4158.9621 | L43: =I43/E10-1 -> -0.13999956 | M43: Precio Indiferencia Poroto | O43: =E56-SUM(E62:E75,E76) -> 314.67675 | P43: =O43*$E$20 -> 2454.4786 | Q43: =O43/E14-1 -> -0.057854055
C46: Molienda Indiferencia | E46: =H76/(E56-E60) -> 502.05587 | G46: Precio Indiferencia Pellet | J46: =G60+G76-G57 -> 319.86981 | K46: =J46*$E$20 -> 2494.9845 | L46: =J46/(E12*L15+E14*L17)-1 -> -0.042305953 | M46: Margen de Ventas | O46: =E89 -> 11.676746 | P46: =O46*$E$20 -> 91.078616
C49: Precio de Soja Pizarra Rosario | E49: =F49/E20 -> 327.14103 | F49: =G17+G30 -> 2551.7
E55: U$S/Tn Poroto Soja | F55: U$S/Tn Aceite Soja | G55: U$S/Tn Harina Soja | H55: U$S/Mes | J55: $/Tn Poroto Soja | K55: $/Tn Aceite Soja | L55: $/Tn Harina Soja | M55: $/Mes | O55: Unidades | P55: $/Unidad
B56: Ingresos por Ventas | E56: =H56/$L$20 -> 359.41274 | F56: =H56/($L$20*(1-$E$37)*$L$10) -> 2671.7143 | G56: =H56/($L$20*(1-$E$37)*$L$12) -> 434.93023 | H56: =SUM(H57:H59) -> 233618.28 | J56: =E56*$E$20 -> 2803.4194 | K56: =F56*$E$20 -> 20839.371 | L56: =G56*$E$20 -> 3392.4558 | M56: =H56*$E$20 -> 1822222.6
B57: * | C57: Aceite de Soja | E57: =H57/$L$20 -> 83.405587 | F57: =H57/($L$20*(1-$E$37)*$L$10) -> 620 | G57: =H57/($L$20*(1-$E$37)*$L$12) -> 100.93023 | H57: =$L$20*(1-$E$37)*L10*E10 -> 54213.631 | J57: =E57*$E$20 -> 650.56358 | K57: =F57*$E$20 -> 4836 | L57: =G57*$E$20 -> 787.25581 | M57: =H57*$E$20 -> 422866.32
B58: * | C58: Pellet de Soja | E58: =H58/$L$20 -> 276.00715 | F58: =H58/($L$20*(1-$E$37)*$L$10) -> 2051.7143 | G58: =H58/($L$20*(1-$E$37)*$L$12) -> 334 | H58: =$L$20*(1-$E$37)*L12*E12 -> 179404.65 | J58: =E58*$E$20 -> 2152.8558 | K58: =F58*$E$20 -> 16003.371 | L58: =G58*$E$20 -> 2605.2 | M58: =H58*$E$20 -> 1399356.3
B59: * | C59: Harina de Soja | E59: =H59/$L$20 -> 0 | F59: =H59/($L$20*(1-$E$37)*$L$10) -> 0 | G59: =H59/($L$20*(1-$E$37)*$L$12) -> 0 | H59: =$L$20*(1-$E$37)*L12*E14*L17 -> 0 | J59: =E59*$E$20 -> 0 | K59: =F59*$E$20 -> 0 | L59: =G59*$E$20 -> 0 | M59: =H59*$E$20 -> 0
B60: Costos Variables | E60: =H60/$L$20 -> 308.11037 | F60: =H60/($L$20*(1-$E$37)*$L$10) -> 2290.3553 | G60: =H60/($L$20*(1-$E$37)*$L$12) -> 372.84854 | H60: =SUM(H61:H75) -> 200271.74 | J60: =E60*$E$20 -> 2403.2609 | K60: =F60*$E$20 -> 17864.771 | L60: =G60*$E$20 -> 2908.2186 | M60: =H60*$E$20 -> 1562119.6
B61: * | C61: Poroto de Soja | E61: =H61/$L$20 -> 303 | F61: =H61/($L$20*(1-$E$37)*$L$10) -> 2252.3671 | G61: =H61/($L$20*(1-$E$37)*$L$12) -> 366.66441 | H61: =E17*L20 -> 196950 | J61: =E61*$E$20 -> 2363.4 | K61: =F61*$E$20 -> 17568.463 | L61: =G61*$E$20 -> 2859.9824 | M61: =H61*$E$20 -> 1536210
B62: * | C62: Comisión de Compra | E62: =H62/$L$20 -> 0 | F62: =H62/($L$20*(1-$E$37)*$L$10) -> 0 | G62: =H62/($L$20*(1-$E$37)*$L$12) -> 0 | H62: =O62*P62 -> 0 | J62: =E62*$E$20 -> 0 | K62: =F62*$E$20 -> 0 | L62: =G62*$E$20 -> 0 | M62: =H62*$E$20 -> 0 | O62: =H61 -> 196950 | P62: =E32 -> 0
B63: * | C63: Comisión de Venta Aceite | E63: =H63/$L$20 -> 0.41702793 | F63: =H63/($L$20*(1-$E$37)*$L$10) -> 3.1 | G63: =H63/($L$20*(1-$E$37)*$L$12) -> 0.50465116 | H63: =O63*P63 -> 271.06816 | J63: =E63*$E$20 -> 3.2528179 | K63: =F63*$E$20 -> 24.18 | L63: =G63*$E$20 -> 3.9362791 | M63: =H63*$E$20 -> 2114.3316 | O63: =H57 -> 54213.631 | P63: =E33 -> 0.005
B64: * | C64: Comisión de Venta Harina | E64: =H64/$L$20 -> 1.3800358 | F64: =H64/($L$20*(1-$E$37)*$L$10) -> 10.258571 | G64: =H64/($L$20*(1-$E$37)*$L$12) -> 1.67 | H64: =O64*P64 -> 897.02324 | J64: =E64*$E$20 -> 10.764279 | K64: =F64*$E$20 -> 80.016857 | L64: =G64*$E$20 -> 13.026 | M64: =H64*$E$20 -> 6996.7813 | O64: =H58 -> 179404.65 | P64: =E34 -> 0.005
...

Sheet Fazon
F2: Aceitera de Soja | H2: Desarrollado por Simpleza S.A.
F3: Tablero Fazon
B7: Soja Ingreso | C7: 1000 | D7: Kg
B10: Costo Molienda | C10: =Molienda!J76+SUM(Molienda!J68:J75) -> 334.92364 | D10: $/Tn Ingreso
B13: Efec. Proceso | C13: =1-Molienda!E37 -> 0.96089385
B14: Soja Molida | C14: =C7*C13 -> 960.89385 | D14: Kg
B17: Expeller | C17: =C14*Molienda!L12 -> 826.36872 | D17: Kg
B18: Aceite | C18: =Molienda!L10*Fazon!C14 -> 134.52514 | D18: Kg
C21: Retiro Dueño Soja | E21: Saldo Pampa Gringa | G21: Valor Neto
B22: Expeller | C22: 900 | D22: Kg | E22: =C17-C22 -> -73.631285 | F22: Kg | G22: =Molienda!G12*(1-Molienda!E34)-Molienda!G27 -> 2592.174 | H22: $/Kg
B23: Aceite | C23: 0 | D23: Kg | E23: =C18-C23 -> 134.52514 | F23: Kg | G23: =Molienda!G10*(1-Molienda!E33)-Molienda!G26 -> 4811.82 | H23: $/Kg
B25: Ingreso | C25: =SUMPRODUCT(E22:E23,G22:G23)/1000*C13 -> 438.59583 | D25: $/Tn Soja Ingresada
B26: Costo | C26: =C10 -> 334.92364 | D26: $/Tn Soja Ingresada
B28: Margen | C28: =C25-C26 -> 103.67219 | D28: $/Tn Soja Ingresada
C29: =C28/Molienda!E20 -> 13.291306 | D29: U$S/Tn Soja Ingresada
B40: 1

Sheet Instructivo
F3: Aceitera de Soja | J3: Desarrollado por Simpleza S.A.
F4: Tablero de Sensibilidad del Negocio.
B7: El objetivo de este tablero es realizar el calculo de resultados de moler soja
B8: y vender los subproductos.
B9: Teniendo en cuenta los costos de estructura dde Agroindustria Pampa
B11: Modo de uso
B13: En la hoja Molienda se podrán modificar las siguientes variables
B15: * Precio de venta de aceite de soja ($/tn) | F15: * Rendimiento de subproductos
B16: * Precio de venta de Expeller de soja ($/tn)
B17: * Precio de venta de hariana de soja ($/tn)
B18: * Precio de compra de Soja poroto ($/tn) - precio neto que cobra el cliente
B19: * Tipo de cambio
B21: * Costo de secada para clientes ($/tn)
B23: * Fletes a planta (de soja poroto)
B24: * Flete campo a puerto (es el dto a realzar al cliente)
B25: * Comisiones
B26: * Molienda de soja poroto

Sheet Flete y Mermas
B1: $/Km
A2: 1 | B2: 25.3
A3: 2 | B3: 25.3
A4: 3 | B4: 25.3
A5: 4 | B5: 25.3
A6: 5 | B6: 25.3
A7: 6 | B7: 25.3
A8: 7 | B8: 25.3
A9: 8 | B9: 25.3
A10: 9 | B10: 25.3
A11: 10 | B11: 25.3
A12: 11 | B12: 25.83
A13: 12 | B13: 26.35
... A1001: 1000 | B1001: 395

Sheet Coberturas
A3: Condciones a hoy
B4: Aceite usd 755 (o 735 + iva) comision 1% flete usd 25/tn
B5: Pellets 88% precio pizarra menos flete aprox. 8% comision 0,5%
B6: Compra de soja 91% precio pizarra menos $95/tn
A9: Fecha | B9: Tipo de cobertura | C9: Precio Ejercicio | D9: costo Prima | E9: Valor P mercado | F9: Diferencia
